‚ùå ERROR:
Traceback (most recent call last):
  File "/Users/Gopal/Desktop/Dac-PS/ai-test-automation-poc/backend/test_executor.py", line 26, in execute_test_script
    result = subprocess.run(["python", file_path], capture_output=True, text=True)
  File "/Library/Developer/CommandLineTools/Library/Frameworks/Python3.framework/Versions/3.9/lib/python3.9/subprocess.py", line 505, in run
    with Popen(*popenargs, **kwargs) as process:
  File "/Library/Developer/CommandLineTools/Library/Frameworks/Python3.framework/Versions/3.9/lib/python3.9/subprocess.py", line 951, in __init__
    self._execute_child(args, executable, preexec_fn, close_fds,
  File "/Library/Developer/CommandLineTools/Library/Frameworks/Python3.framework/Versions/3.9/lib/python3.9/subprocess.py", line 1821, in _execute_child
    raise child_exception_type(errno_num, err_msg, err_filename)
FileNotFoundError: [Errno 2] No such file or directory: 'python'
